Internal Server Error: /langs
Traceback (most recent call last):
  File "/usr/local/lib/python3.7/site-packages/django/core/handlers/exception.py", line 34, in inner
    response = get_response(request)
  File "/usr/local/lib/python3.7/site-packages/django/core/handlers/base.py", line 156, in _get_response
    response = self.process_exception_by_middleware(e, request)
  File "/usr/local/lib/python3.7/site-packages/django/core/handlers/base.py", line 154, in _get_response
    response = response.render()
  File "/usr/local/lib/python3.7/site-packages/django/template/response.py", line 106, in render
    self.content = self.rendered_content
  File "/usr/local/lib/python3.7/site-packages/django/template/response.py", line 81, in rendered_content
    template = self.resolve_template(self.template_name)
  File "/usr/local/lib/python3.7/site-packages/django/template/response.py", line 63, in resolve_template
    return select_template(template, using=self.using)
  File "/usr/local/lib/python3.7/site-packages/django/template/loader.py", line 42, in select_template
    return engine.get_template(template_name)
  File "/usr/local/lib/python3.7/site-packages/django/template/backends/django.py", line 34, in get_template
    return Template(self.engine.get_template(template_name), self)
  File "/usr/local/lib/python3.7/site-packages/django/template/engine.py", line 144, in get_template
    template, origin = self.find_template(template_name)
  File "/usr/local/lib/python3.7/site-packages/django/template/engine.py", line 126, in find_template
    template = loader.get_template(name, skip=skip)
  File "/usr/local/lib/python3.7/site-packages/django/template/loaders/base.py", line 30, in get_template
    contents, origin, origin.template_name, self.engine,
  File "/usr/local/lib/python3.7/site-packages/django/template/base.py", line 156, in __init__
    self.nodelist = self.compile_nodelist()
  File "/usr/local/lib/python3.7/site-packages/django/template/base.py", line 194, in compile_nodelist
    return parser.parse()
  File "/usr/local/lib/python3.7/site-packages/django/template/base.py", line 479, in parse
    self.extend_nodelist(nodelist, compiled_result, token)
  File "/usr/local/lib/python3.7/site-packages/django/template/base.py", line 497, in extend_nodelist
    token, '%r must be the first tag in the template.' % node,
django.template.exceptions.TemplateSyntaxError: <ExtendsNode: extends "base.html"> must be the first tag in the template.
Internal Server Error: /i18n/setlang/
Traceback (most recent call last):
  File "/usr/local/lib/python3.7/site-packages/django/db/backends/utils.py", line 85, in _execute
    return self.cursor.execute(sql, params)
psycopg2.ProgrammingError: relation "django_session" does not exist
LINE 1: SELECT (1) AS "a" FROM "django_session" WHERE "django_sessio...
                               ^


The above exception was the direct cause of the following exception:

Traceback (most recent call last):
  File "/usr/local/lib/python3.7/site-packages/django/core/handlers/exception.py", line 34, in inner
    response = get_response(request)
  File "/usr/local/lib/python3.7/site-packages/django/utils/deprecation.py", line 93, in __call__
    response = self.process_response(request, response)
  File "/usr/local/lib/python3.7/site-packages/django/contrib/sessions/middleware.py", line 58, in process_response
    request.session.save()
  File "/usr/local/lib/python3.7/site-packages/django/contrib/sessions/backends/db.py", line 81, in save
    return self.create()
  File "/usr/local/lib/python3.7/site-packages/django/contrib/sessions/backends/db.py", line 51, in create
    self._session_key = self._get_new_session_key()
  File "/usr/local/lib/python3.7/site-packages/django/contrib/sessions/backends/base.py", line 153, in _get_new_session_key
    if not self.exists(session_key):
  File "/usr/local/lib/python3.7/site-packages/django/contrib/sessions/backends/db.py", line 47, in exists
    return self.model.objects.filter(session_key=session_key).exists()
  File "/usr/local/lib/python3.7/site-packages/django/db/models/query.py", line 718, in exists
    return self.query.has_results(using=self.db)
  File "/usr/local/lib/python3.7/site-packages/django/db/models/sql/query.py", line 516, in has_results
    return compiler.has_results()
  File "/usr/local/lib/python3.7/site-packages/django/db/models/sql/compiler.py", line 1035, in has_results
    return bool(self.execute_sql(SINGLE))
  File "/usr/local/lib/python3.7/site-packages/django/db/models/sql/compiler.py", line 1065, in execute_sql
    cursor.execute(sql, params)
  File "/usr/local/lib/python3.7/site-packages/django/db/backends/utils.py", line 100, in execute
    return super().execute(sql, params)
  File "/usr/local/lib/python3.7/site-packages/django/db/backends/utils.py", line 68, in execute
    return self._execute_with_wrappers(sql, params, many=False, executor=self._execute)
  File "/usr/local/lib/python3.7/site-packages/django/db/backends/utils.py", line 77, in _execute_with_wrappers
    return executor(sql, params, many, context)
  File "/usr/local/lib/python3.7/site-packages/django/db/backends/utils.py", line 85, in _execute
    return self.cursor.execute(sql, params)
  File "/usr/local/lib/python3.7/site-packages/django/db/utils.py", line 89, in __exit__
    raise dj_exc_value.with_traceback(traceback) from exc_value
  File "/usr/local/lib/python3.7/site-packages/django/db/backends/utils.py", line 85, in _execute
    return self.cursor.execute(sql, params)
django.db.utils.ProgrammingError: relation "django_session" does not exist
LINE 1: SELECT (1) AS "a" FROM "django_session" WHERE "django_sessio...
                               ^

